ITC172- Asmts 8 & 9 - TEST ERROR LOG
-----------------------------------------

C:\PythonClub>python manage.py test -v 2
Creating test database for alias 'default' ('test_PythonClubdb')...
Operations to perform:
  Synchronize unmigrated apps: messages, staticfiles
  Apply all migrations: Club, admin, auth, contenttypes, sessions
Synchronizing apps without migrations:
  Creating tables...
    Running deferred SQL...
Running migrations:
  Applying contenttypes.0001_initial... OK
  Applying auth.0001_initial... OK
  Applying Club.0001_initial... OK
  Applying admin.0001_initial... OK
  Applying admin.0002_logentry_remove_auto_add... OK
  Applying admin.0003_logentry_add_action_flag_choices... OK
  Applying contenttypes.0002_remove_content_type_name... OK
  Applying auth.0002_alter_permission_name_max_length... OK
  Applying auth.0003_alter_user_email_max_length... OK
  Applying auth.0004_alter_user_username_opts... OK
  Applying auth.0005_alter_user_last_login_null... OK
  Applying auth.0006_require_contenttypes_0002... OK
  Applying auth.0007_alter_validators_add_error_messages... OK
  Applying auth.0008_alter_user_username_max_length... OK
  Applying auth.0009_alter_user_last_name_max_length... OK
  Applying auth.0010_alter_group_name_max_length... OK
  Applying auth.0011_update_proxy_permissions... OK
  Applying sessions.0001_initial... OK
System check identified no issues (0 silenced).
test_string (Club.tests.EventTest) ... ok
test_table (Club.tests.EventTest) ... ok
test_view_url_accessible_by_name (Club.tests.GetEvents) ... ok
test_view_url_accessible_by_name (Club.tests.GetMeetings) ... ok
test_view_url_accessible_by_name (Club.tests.GetResources) ... ok
test_view_url_accessible_by_name (Club.tests.IndexTest) ... ok
test_string (Club.tests.MeetingTest) ... ok
test_table (Club.tests.MeetingTest) ... ok
test_string (Club.tests.MinutesTest) ... ok
test_table (Club.tests.MinutesTest) ... ok
test_Logged_in_uses_correct_template (Club.tests.New_Resource_authentication_test) ... ERROR
test_redirect_if_not_logged_in (Club.tests.New_Resource_authentication_test) ... ERROR
test_string (Club.tests.ResourcesTest) ... ok
test_table (Club.tests.ResourcesTest) ... ok
test_type (Club.tests.ResourcesTest) ... ok

======================================================================
ERROR: test_Logged_in_uses_correct_template (Club.tests.New_Resource_authentication_test)
----------------------------------------------------------------------
Traceback (most recent call last):
  File "C:\Users\zenso\AppData\Local\Programs\Python\Python38-32\lib\site-packages\django\db\backends\utils.py", line 86, in _execute
    return self.cursor.execute(sql, params)
psycopg2.errors.NotNullViolation: null value in column "dateentered" violates not-null constraint
DETAIL:  Failing row contains (1, redline, null, null, null, , null).


The above exception was the direct cause of the following exception:

Traceback (most recent call last):
  File "C:\PythonClub\Club\tests.py", line 75, in setUp
    self.name=Resource.objects.create (resourcename='redline')
  File "C:\Users\zenso\AppData\Local\Programs\Python\Python38-32\lib\site-packages\django\db\models\manager.py", line 82, in manager_method
    return getattr(self.get_queryset(), name)(*args, **kwargs)
  File "C:\Users\zenso\AppData\Local\Programs\Python\Python38-32\lib\site-packages\django\db\models\query.py", line 433, in create
    obj.save(force_insert=True, using=self.db)
  File "C:\Users\zenso\AppData\Local\Programs\Python\Python38-32\lib\site-packages\django\db\models\base.py", line 745, in save
    self.save_base(using=using, force_insert=force_insert,
  File "C:\Users\zenso\AppData\Local\Programs\Python\Python38-32\lib\site-packages\django\db\models\base.py", line 782, in save_base
    updated = self._save_table(
  File "C:\Users\zenso\AppData\Local\Programs\Python\Python38-32\lib\site-packages\django\db\models\base.py", line 887, in _save_table
    results = self._do_insert(cls._base_manager, using, fields, returning_fields, raw)
  File "C:\Users\zenso\AppData\Local\Programs\Python\Python38-32\lib\site-packages\django\db\models\base.py", line 924, in _do_insert
    return manager._insert(
  File "C:\Users\zenso\AppData\Local\Programs\Python\Python38-32\lib\site-packages\django\db\models\manager.py", line 82, in manager_method
    return getattr(self.get_queryset(), name)(*args, **kwargs)
  File "C:\Users\zenso\AppData\Local\Programs\Python\Python38-32\lib\site-packages\django\db\models\query.py", line 1204, in _insert
    return query.get_compiler(using=using).execute_sql(returning_fields)
  File "C:\Users\zenso\AppData\Local\Programs\Python\Python38-32\lib\site-packages\django\db\models\sql\compiler.py", line 1384, in execute_sql
    cursor.execute(sql, params)
  File "C:\Users\zenso\AppData\Local\Programs\Python\Python38-32\lib\site-packages\django\db\backends\utils.py", line 68, in execute
    return self._execute_with_wrappers(sql, params, many=False, executor=self._execute)
  File "C:\Users\zenso\AppData\Local\Programs\Python\Python38-32\lib\site-packages\django\db\backends\utils.py", line 77, in _execute_with_wrappers
    return executor(sql, params, many, context)
  File "C:\Users\zenso\AppData\Local\Programs\Python\Python38-32\lib\site-packages\django\db\backends\utils.py", line 86, in _execute
    return self.cursor.execute(sql, params)
  File "C:\Users\zenso\AppData\Local\Programs\Python\Python38-32\lib\site-packages\django\db\utils.py", line 90, in __exit__
    raise dj_exc_value.with_traceback(traceback) from exc_value
  File "C:\Users\zenso\AppData\Local\Programs\Python\Python38-32\lib\site-packages\django\db\backends\utils.py", line 86, in _execute
    return self.cursor.execute(sql, params)
django.db.utils.IntegrityError: null value in column "dateentered" violates not-null constraint
DETAIL:  Failing row contains (1, redline, null, null, null, , null).


======================================================================
ERROR: test_redirect_if_not_logged_in (Club.tests.New_Resource_authentication_test)
----------------------------------------------------------------------
Traceback (most recent call last):
  File "C:\Users\zenso\AppData\Local\Programs\Python\Python38-32\lib\site-packages\django\db\backends\utils.py", line 86, in _execute
    return self.cursor.execute(sql, params)
psycopg2.errors.NotNullViolation: null value in column "dateentered" violates not-null constraint
DETAIL:  Failing row contains (2, redline, null, null, null, , null).


The above exception was the direct cause of the following exception:

Traceback (most recent call last):
  File "C:\PythonClub\Club\tests.py", line 75, in setUp
    self.name=Resource.objects.create (resourcename='redline')
  File "C:\Users\zenso\AppData\Local\Programs\Python\Python38-32\lib\site-packages\django\db\models\manager.py", line 82, in manager_method
    return getattr(self.get_queryset(), name)(*args, **kwargs)
  File "C:\Users\zenso\AppData\Local\Programs\Python\Python38-32\lib\site-packages\django\db\models\query.py", line 433, in create
    obj.save(force_insert=True, using=self.db)
  File "C:\Users\zenso\AppData\Local\Programs\Python\Python38-32\lib\site-packages\django\db\models\base.py", line 745, in save
    self.save_base(using=using, force_insert=force_insert,
  File "C:\Users\zenso\AppData\Local\Programs\Python\Python38-32\lib\site-packages\django\db\models\base.py", line 782, in save_base
    updated = self._save_table(
  File "C:\Users\zenso\AppData\Local\Programs\Python\Python38-32\lib\site-packages\django\db\models\base.py", line 887, in _save_table
    results = self._do_insert(cls._base_manager, using, fields, returning_fields, raw)
  File "C:\Users\zenso\AppData\Local\Programs\Python\Python38-32\lib\site-packages\django\db\models\base.py", line 924, in _do_insert
    return manager._insert(
  File "C:\Users\zenso\AppData\Local\Programs\Python\Python38-32\lib\site-packages\django\db\models\manager.py", line 82, in manager_method
    return getattr(self.get_queryset(), name)(*args, **kwargs)
  File "C:\Users\zenso\AppData\Local\Programs\Python\Python38-32\lib\site-packages\django\db\models\query.py", line 1204, in _insert
    return query.get_compiler(using=using).execute_sql(returning_fields)
  File "C:\Users\zenso\AppData\Local\Programs\Python\Python38-32\lib\site-packages\django\db\models\sql\compiler.py", line 1384, in execute_sql
    cursor.execute(sql, params)
  File "C:\Users\zenso\AppData\Local\Programs\Python\Python38-32\lib\site-packages\django\db\backends\utils.py", line 68, in execute
    return self._execute_with_wrappers(sql, params, many=False, executor=self._execute)
  File "C:\Users\zenso\AppData\Local\Programs\Python\Python38-32\lib\site-packages\django\db\backends\utils.py", line 77, in _execute_with_wrappers
    return executor(sql, params, many, context)
  File "C:\Users\zenso\AppData\Local\Programs\Python\Python38-32\lib\site-packages\django\db\backends\utils.py", line 86, in _execute
    return self.cursor.execute(sql, params)
  File "C:\Users\zenso\AppData\Local\Programs\Python\Python38-32\lib\site-packages\django\db\utils.py", line 90, in __exit__
    raise dj_exc_value.with_traceback(traceback) from exc_value
  File "C:\Users\zenso\AppData\Local\Programs\Python\Python38-32\lib\site-packages\django\db\backends\utils.py", line 86, in _execute
    return self.cursor.execute(sql, params)
django.db.utils.IntegrityError: null value in column "dateentered" violates not-null constraint
DETAIL:  Failing row contains (2, redline, null, null, null, , null).


----------------------------------------------------------------------
Ran 15 tests in 1.749s

FAILED (errors=2)